Workbook

Sheet SOCIALIZAÇÃO
A1: Legendas: S – Sim (alcançou) | N – Não (ainda não alcançou) | AV - Às vezes Obs: Marque utilizando as legendas acima, baseado no Manual do Inventário Operacionalizado Portage. Para dicas, instruções e a tabela de cálculo automático da idade de desenvolvimento, acesse o e-book Como Adaptar Atividades para Alunos com Deficiência: aprenda a identificar as necessidades do seu aluno e adaptar atividades, no site do Instituto Itard
A3: Socialização
A4: N.º | B4: Verificar se: | C4: Critério | D4: Resultado | E4: Idade
A5: 1 | B5: Observa uma pessoa movimentando-se em seu campo visual. | C5: Olhar e seguir com o olhar uma pessoa em movimento, dentro de 20s após o inicio do movimento. | D5: s | E5: 0 a 1
A6: 2 | B6: Sorri em resposta à atenção do adulto. | C6: Sorrir dentro de 10s após o adulto dar "atençao". | D6: s | E6: 0 a 1
A7: 3 | B7: Vocaliza em resposta à atenção. | C7: Apresentar qualquer tipo de vocalização dentro de 10s após a "atenção" do adulto. | D7: s | E7: 0 a 1
A8: 4 | B8: Olha para sua própria mão, sorrindo ou vocalizando. | C8: Permanecer olhando por 5s em direção a sua mão, sorrindo ou vocalizando pelo menos uma vez em três tentativas. | D8: s | E8: 0 a 1
A9: 5 | B9: Responde a seu círculo familiar, sorrindo, vocalizando ou parando de chorar. | C9: Responder com sorriso, vocalização ou parar de chorar dentro de 10s após a atenção do familiar. (Perguntar aos responsáveis) | D9: s | E9: 0 a 1
A10: 6 | B10: Sorri em resposta à expressão facial dos outros. | C10: Sorrir em resposta à expressão facial dos outros dentro de 10s após tal expressão. | D10: s | E10: 0 a 1
A11: 7 | B11: Sorri e vocaliza ao ver sua imagem no espelho | C11: Sorrir e vocalizar dentro de 10s ao olhar-se no espelho. | D11: s | E11: 0 a 1
A12: 8 | B12: Acaricia ou toca no rosto de adultos (puxa cabelo, nariz, óculos, etc.). | C12: Tocar no rosto do adulto ou puxar cabelo ou óculos. | D12: s | E12: 0 a 1
A13: 9 | B13: Estende a mão em direção a um objeto oferecido. | C13: Estender a mão em relação a um objeto que lhe é oferecido dentro de 20s. | D13: s | E13: 0 a 1
A14: 10 | B14: Estende os braços em direção a pessoas familiares. | C14: Estender os braços em direção a pelo menos dois familiares diferentes. | D14: s | E14: 0 a 1
A15: 11 | B15: Estende a mão e toca sua imagem refletida no espelho. | C15: Estender a mão e tocar dentro de 20s. | D15: s | E15: 0 a 1
A16: 12 | B16: Segura e examina por 1 minuto um objeto que lhe foi dado. | C16: Olhar e manupular um objeto por pelo menos 1m, tal resposta deverá ser iniciada dentro de 20s após a apresentação do objeto. | D16: s | E16: 0 a 1
A17: 13 | B17: Sacode ou aperta um objeto colocado em sua mão, produzindo sons involuntários. | D17: s | E17: 0 a 1
A18: 14 | B18: Brinca sozinho por 10 minutos. | D18: s | E18: 0 a 1
A19: 15 | B19: Procura contato visual quando alguém lhe dá atenção por 2 a 3 minutos. | C19: Olhar pelo menos 5 vezes quando alguém lhe der "atenção" por 2 à 3 min. | D19: s | E19: 0 a 1
A20: 16 | B20: Brinca sozinho sem reclamar por 15 a 20 minutos, próximo de um adulto. | D20: s | E20: 0 a 1
A21: 17 | B21: Vocaliza para obter atenção. | C21: Entrevista com os responsáveis. | D21: s | E21: 0 a 1
A22: 18 | B22: Imita adulto em brincadeiras de esconde. | C22: Imitar dentro de 10s após o modelo do adulto. | D22: s | E22: 0 a 1
A23: 19 | B23: Bate palmas, imitando um adulto. | C23: Bater palmas dentro de 10s após o modelo. | D23: s | E23: 0 a 1
A24: 20 | B24: Acena a mão, imitando um adulto. | C24: Imitar dentro de 10s após o modelo do adulto. | D24: s | E24: 0 a 1
A25: 21 | B25: Ergue os braços para expressar “grande”, imitando um adulto. | C25: Dentro de 10s após o modelo do adulto. | D25: s | E25: 0 a 1
A26: 22 | B26: Oferece algo, mas nem sempre entrega. | C26: Oferecer e entregar pelo menos uma vez em quatro tentativas. | D26: s | E26: 0 a 1
A27: 23 | B27: Abraça, acaricia e beija familiares. | C27: Dizer a criança "Dá um beijo na mamãe", por exemplo. Demonstrar por modelo, se necessário. | D27: s | E27: 0 a 1
A28: 24 | B28: Responde ao próprio nome, olhando ou estendendo o braço para ser pego. | C28: Dentro de 20s após a emissão de seu nome. | D28: s | E28: 0 a 1
A29: 25 | B29: Aperta ou sacode um brinquedo para produzir sons, em imitação. | C29: Dentro de 10s após o modelo do adulto. | D29: s | E29: 0 a 1
A30: 26 | B30: Manipula brinquedo ou objeto. | C30: Se necessário, dar modelo e solicitar a resposta. | D30: s | E30: 0 a 1
A31: 27 | B31: Estende um brinquedo ou objeto a um adulto e o entrega. | C31: Apresentar vários objetos e quando esta estiver segurando, solicitar de volta. | D31: s | E31: 0 a 1
A32: 28 | B32: Imita movimentos de outras crianças ao brincar. | C32: imitar pelo menos dois movimentos diferentes. | D32: s | E32: 0 a 1
... A35: 31 | B35: Toma parte em uma brincadeira com outra criança por 2 a 5 minutos. | C35: Permanecer por 2 à 5 min compartilhando o mesmo objeto com outra criança. | D35: S | E35: 1 a 2
A36: 32 | B36: Aceita a ausência dos pais, embora possa reclamar. | D36: S | E36: 1 a 2
A37: 33 | B37: Explora ativamente seu meio ambiente. | C37: Entrevista com o responsável. | D37: S | E37: 1 a 2
A38: 34 | B38: Realiza atividade manipulativa com outra pessoa. | D38: S | E38: 1 a 2
A39: 35 | B39: Abraça e carrega uma boneca ou brinquedo macio. | C39: Dar modelo e solocitar a resposta. A criança precisa dar pelo menos 5 passos, abraçando e carregando o objeto. | D39: S | E39: 1 a 2
A40: 36 | B40: Repete ações que produzem risos e atenção. | C40: Repetir pelo menos em duas ocasiões diferentes, ações que produzam riso ou atenção. | D40: S | E40: 1 a 2
A41: 37 | B41: Dá um livro para que um adulto o leia ou para que ambos o compartilhem. | C41: Por pelo menos 2 min. | D41: S | E41: 1 a 2
A42: 38 | B42: Puxa uma pessoa para mostrar-lhe alguma ação ou objeto. | D42: S | E42: 1 a 2
A43: 39 | B43: Retira a mão ou diz "não" quando está próximo de um objeto não permitido e alguém o lembra disto. | D43: S | E43: 1 a 2
...

Sheet LINGUAGEM
A1: Legendas: S – Sim (alcançou) | N – Não (ainda não alcançou) | AV - Às vezes Obs: Marque utilizando as legendas acima, baseado no Manual do Inventário Operacionalizado Portage. Para dicas, instruções e a tabela de cálculo automático da idade de desenvolvimento, acesse o e-book Como Adaptar Atividades para Alunos com Deficiência: aprenda a identificar as necessidades do seu aluno e adaptar atividades, no site do Instituto Itard
A3: Linguagem
A4: N.º | B4: Verificar se: | C4: Critério | D4: Resultado | E4: Idade
A5: 1 | B5: Repete sons emitidos por outras pessoas. | C5: Produzir sons curtos uma ou duas vezes. Repetir sons semelhantes ao modelo dentro de 1 min. | D5: s | E5: 0 a 1
A6: 2 | B6: Repete a mesma sílaba 2 a 3 vezes. (ma, ma, ma). | D6: s | E6: 0 a 1
A7: 3 | B7: Responde a gestos com gestos. | C7: Responder a pelo menos dois gestos diferentes, com gestos, exemplo: dar tchau, aplaudir, mover a cabeça negativamente "não", estender os braços para ser pego, jogar um beijo, etc. | D7: s | E7: 0 a 1
A8: 4 | B8: Obedece a uma ordem simples, quando acompanhada de gestos indicativos. | D8: s | E8: 0 a 1
A9: 5 | B9: Interrompe a atividade quando lhe dizem "Não" 75% das vezes. | D9: s | E9: 0 a 1
A10: 6 | B10: Responde a perguntas simples com respostas não verbais. | D10: s | E10: 0 a 1
A11: 7 | B11: Combina 2 sílabas diferentes quando tenta verbalizar. | D11: s | E11: 0 a 1
A12: 8 | B12: Imita padrões de entonação da voz de outras pessoas. | C12: Imitar pelo menos dois padrões de entonação de voz diferentes. | D12: s | E12: 0 a 1
A13: 9 | B13: Usa uma palavra funcionalmente para indicar objetos ou pessoas. | D13: s | E13: 0 a 1
A14: 10 | B14: Vocaliza em resposta à fala de outras pessoas. | C14: Apresentar qualquer tipo de vocalização 1 à 2s após a fala de outra pessoa. | D14: s | E14: 0 a 1
A15: 11 | B15: Diz 5 palavras diferentes. | D15: s | E15: 1 a 2
A16: 12 | B16: Pede "mais". | D16: s | E16: 1 a 2
A17: 13 | B17: Diz "acabou". | D17: s | E17: 1 a 2
A18: 14 | B18: Obedece a 3 ordens diferentes que não são acompanhadas de gestos indicativos. | D18: s | E18: 1 a 2
A19: 15 | B19: Consegue "dar" ou "mostrar" quando solicitado. | D19: s | E19: 1 a 2
A20: 16 | B20: Aponta para 12 objetos quando nomeados. | D20: s | E20: 1 a 2
A21: 17 | B21: Aponta para 3 a 5 figuras em um livro. | D21: s | E21: 1 a 2
A22: 18 | B22: Aponta para 3 partes de seu próprio corpo. | D22: s | E22: 1 a 2
A23: 19 | B23: Diz seu nome ou apelido quando solicitado. | D23: s | E23: 1 a 2
A24: 20 | B24: Responde à pergunta "O que é isto?" com o nome do objeto. | D24: s | E24: 1 a 2
A25: 21 | B25: Combina palavras e gestos para expressar desejos. | D25: s | E25: 1 a 2
A26: 22 | B26: Nomeia 5 membros da família, incluindo animais domésticos. | D26: s | E26: 1 a 2
... A32: 28 | B32: Responde a perguntas de sim / não. | D32: s | E32: 1 a 2
A33: 29 | B33: Combina substantivos ou adjetivos e substantivos em frases de 2 palavras. | C33: Apresentar pelo menos 3 frases que combinam substantivos ou adjetivos e substantivos. | D33: s | E33: 2 a 3
A34: 30 | B34: Combina substantivo e verbo em frases de 2 palavras | C34: Apresenta pelo menos 3 frases de duas palavras que combinem substantivo e verbo. | D34: s | E34: 2 a 3
A35: 31 | B35: Usa uma palavra para indicar que quer ir ao banheiro | C35: Entrevista com os responsáveis | D35: s | E35: 2 a 3
A36: 32 | B36: Combina verbo ou substantivo com "lá" e "aqui" em frases de 2 palavras. | D36: s | E36: 2 a 3
A37: 33 | B37: Combina 2 palavras para expressar posse. | D37: s | E37: 2 a 3
A38: 34 | B38: Emprega "não" na fala. | C38: Formar frases de duas a três palavras contendo a palavra "não". | D38: s | E38: 2 a 3
A39: 35 | B39: Responde à pergunta "O que .... está fazendo?" para atividade habituais. | D39: s | E39: 2 a 3
A40: 36 | B40: Responde a perguntas tipo "Onde está objeto?" | D40: s | E40: 2 a 3
A41: 37 | B41: Nomeia sons ambientais familiares. | C41: Nomear pelo menos três diferentes sons ambientais familiares. | D41: s | E41: 2 a 3
A42: 38 | B42: Dá mais de um objeto quando se usa a forma plural na solicitação. | D42: s | E42: 2 a 3
A43: 39 | B43: Ao falar, refere se a si próprio pelo nome. | D43: s | E43: 2 a 3
A44: 40 | B44: Aponta para figuras de objetos comuns descritos pelo uso (até 10) ("O que se usa pra comer? = colher") | D44: s | E44: 2 a 3
A45: 41 | B45: Mostra a idade pelos dedos. | C45: Perguntar à criança: " Me mostre com os dedos quantos anos você tem". | D45: s | E45: 2 a 3
A46: 42 | B46: Diz seu sexo quando solicitado. | D46: s | E46: 2 a 3
...

Sheet AUTOS CUIDADOS
A1: Legendas: S – Sim (alcançou) | N – Não (ainda não alcançou) | AV - Às vezes Obs: Marque utilizando as legendas acima, baseado no Manual do Inventário Operacionalizado Portage. Para dicas, instruções e a tabela de cálculo automático da idade de desenvolvimento, acesse o e-book Como Adaptar Atividades para Alunos com Deficiência: aprenda a identificar as necessidades do seu aluno e adaptar atividades, no site do Instituto Itard
A3: Autos Cuidados
A4: N.º | B4: Verificar se: | C4: Critério | D4: Resultado | E4: Idade
A5: 1 | B5: Suga e deglute líquidos. | D5: s | E5: 0 a 1
A6: 2 | B6: Toma mingau / sopinha. | D6: s | E6: 0 a 1
A7: 3 | B7: Estende as mãos em direção a mamadeira, tentando pegá-la | D7: s | E7: 0 a 1
A8: 4 | B8: Come alimentos liquidificados dados pelos pais. | D8: s | E8: 0 a 1
A9: 5 | B9: Segura a mamadeira sem ajuda enquanto bebe. | D9: s | E9: 0 a 1
A10: 6 | B10: Leva a mamadeira até a boca ou a recusa, empurrando-a | D10: s | E10: 0 a 1
A11: 7 | B11: Come alimentos amassados dados pelos pais. | D11: s | E11: 0 a 1
A12: 8 | B12: Bebe em uma caneca, segurada pelos pais. | D12: s | E12: 0 a 1
A13: 9 | B13: Come alimentos semissólidos dados pelos pais. | D13: s | E13: 0 a 1
A14: 10 | B14: Alimenta se sozinho usando os dedos. | D14: s | E14: 0 a 1
A15: 11 | B15: Segura a caneca com ambas as mãos e bebe. | D15: s | E15: 0 a 1
A16: 12 | B16: Leva a colher cheia de comida até a boca com ajuda. | D16: s | E16: 0 a 1
... A109: 105 | B109: Aperta o cinto de segurança do automóvel. | D109: S | E109: 5 a 6

Sheet COGNIÇÃO
A1: Legendas: S – Sim (alcançou) | N – Não (ainda não alcançou) | AV - Às vezes Obs: Marque utilizando as legendas acima, baseado no Manual do Inventário Operacionalizado Portage. Para dicas, instruções e a tabela de cálculo automático da idade de desenvolvimento, acesse o e-book Como Adaptar Atividades para Alunos com Deficiência: aprenda a identificar as necessidades do seu aluno e adaptar atividades, no site do Instituto Itard
A3: Cognição
A4: N.º | B4: Verificar se: | C4: Critério | D4: Resultado | E4: Idade
A5: 1 | B5: Remove um pano do rosto que obscureça sua visão. | D5: S | E5: 0 a 1
A6: 2 | B6: Procura com o olhar um objeto que foi tirado de seu campo visual. | C6: Colocar a criança deitada ou sentada e o objeto distante 15 a 20cm da criança. Esta precisa percorrer com os olhos o percurso do obejto ou virar a cabeça em direção ao local em que o objeto está escondido. | D6: S | E6: 0 a 1
A7: 3 | B7: Remove um objeto de um recipiente colocando a mão dentro do mesmo. | D7: S | E7: 0 a 1
A8: 4 | B8: Coloca um objeto em um recipiente imitando um adulto. | C8: Colocar o objeto dentro de 60s após a apresentação do modelo. | D8: S | E8: 0 a 1
A9: 5 | B9: Coloca um objeto em um recipiente quando recebe instruções. | C9: Colocar o objeto dentro de 60s após a apresentação das instruções. | D9: S | E9: 0 a 1
A10: 6 | B10: Balança um brinquedo que produz som, pendurado em um barbante. | C10: Em 20s após a sua apresentação. | D10: S | E10: 0 a 1
A11: 7 | B11: Coloca três objetos em um recipiente e o esvazia. | D11: S | E11: 0 a 1
A12: 8 | B12: Transfere um objeto de uma mão à outra para apanhar outro objeto. | D12: S | E12: 0 a 1
A13: 9 | B13: Deixa cair e apanha um brinquedo. | D13: S | E13: 0 a 1
A14: 10 | B14: Descobre um objeto escondido sob um recipiente. | D14: S | E14: 0 a 1
A15: 11 | B15: Empurra 3 blocos como se fosse um comboio. | D15: S | E15: 0 a 1
A16: 12 | B16: Remove um círculo de uma prancha, por imitação. | C16: Dar modela à criança, acompanhado de instrução. | D16: S | E16: 0 a 1
A17: 13 | B17: Coloca um pino redondo em uma prancha de pinos, quando solicitado. | D17: S | E17: 0 a 1
A18: 14 | B18: Executa gestos simples quando requisitado | D18: S | E18: 0 a 1
A19: 15 | B19: Retira 6 objetos de um recipiente, um por vez. | D19: S | E19: 1 a 2
A20: 16 | B20: Aponta para uma parte do corpo. | D20: S | E20: 1 a 2
A21: 17 | B21: Empilha 3 blocos, dada a ordem. | C21: A resposta deverá ocorrer dentro de 20s após os blocos terem sido apresentados. | D21: S | E21: 1 a 2
A22: 18 | B22: Emparelha objetos semelhantes. | C22: Emparelhar pelo menos 3 diferentes pares de objetos. | D22: S | E22: 1 a 2
A23: 19 | B23: Faz rabiscos no papel. | C23: Dar modelo e solicitar a resposta (qualquer tipo de rabisco). | D23: S | E23: 1 a 2
A24: 20 | B24: Aponta para si quando perguntam "Cadê o Fulano?" | C24: Se necessário, fazer a pergunta colocando a criança frente ao espelho, ou apresentando-lhe uma fotografia de si mesma. | D24: S | E24: 1 a 2
A25: 21 | B25: Coloca 5 pinos redondos, dada a ordem. | C25: Em 60s após a apresentação dos mesmos. | D25: S | E25: 1 a 2
A26: 22 | B26: Emparelha objetos com a figura do mesmo objeto. | C26: Emparelhar pelo menos 3 objetos diferente com suas respectivas figuras. | D26: S | E26: 1 a 2
A27: 23 | B27: Aponta para a figura nomeada. | D27: S | E27: 1 a 2
A28: 24 | B28: Vira as páginas de um livro (2 à 3 de cada vez) para encontrar a figura nomeada. | D28: S | E28: 1 a 2
A29: 25 | B29: Encontra determinado livro quando solicitado. | D29: S | E29: 2 a 3
A30: 26 | B30: Completa um quebra cabeça de encaixe de 3 peças. | D30: S | E30: 2 a 3
A31: 27 | B31: Nomeia 4 objetos comuns em figuras. | C31: Em 20s após a apresentação de cada figura. | D31: S | E31: 2 a 3
A32: 28 | B32: Desenha uma linha vertical imitando um adulto. | C32: O modelo de linha dado pelo adulto não deve exceder 5 cm. O traço pode ser maior do que o do adulto, mas deverá ter no mínimo 3 cm de comprimento. Este não deve se desviar do modelo mais do que 30 graus. | D32: S | E32: 2 a 3
A33: 29 | B33: Desenha uma linha horizontal imitando um adulto. | C33: O modelo de linha dado pelo adulto não deve exceder 5 cm. O traço pode ser maior do que o do adulto, mas deverá ter no mínimo 3 cm de comprimento. Este não deve se desviar do modelo mais do que 30 graus. | D33: S | E33: 2 a 3
A34: 30 | B34: Copia um círculo. | C34: Apresentar à criança uma folha com um círculo já desenhado (4 cm de diâmetro). Peça a criança para copiar um desenho igual, sem dar sugestões adicionais. A resposta será dada como correta para qualquer forma ovalada fechada, que não seja acompanhada de movimentos concêntricos contínuos. | D34: S | E34: 2 a 3
A35: 31 | B35: Emparelha objetos com a mesma textura. | D35: S | E35: 2 a 3
A36: 32 | B36: Aponta o "pequeno" e o "grande" quando solicitado. | D36: S | E36: 2 a 3
A37: 33 | B37: Desenha (+) imitando um adulto. | C37: O modelo apresentado não deve ser maior que 4 cm. As linhas não precisam estar retas, mas devem se intersectar. | D37: S | E37: 2 a 3
A38: 34 | B38: Emparelha 3 cores. | D38: S | E38: 2 a 3
A39: 35 | B39: Coloca objetos dentro, em cima e em baixo de um recipiente, dada a ordem. | D39: S | E39: 2 a 3
A40: 36 | B40: Nomeia objetos quando ouve o barulho que fazem. | C40: Em 20s após a solicitação de cada resposta. | D40: S | E40: 2 a 3
A41: 37 | B41: Monta um brinquedo de encaixe de 4 peças. | D41: S | E41: 2 a 3
...

Sheet MOTOR
A1: Legendas: S – Sim (alcançou) | N – Não (ainda não alcançou) | AV - Às vezes Obs: Marque utilizando as legendas acima, baseado no Manual do Inventário Operacionalizado Portage. Para dicas, instruções e a tabela de cálculo automático da idade de desenvolvimento, acesse o e-book Como Adaptar Atividades para Alunos com Deficiência: aprenda a identificar as necessidades do seu aluno e adaptar atividades, no site do Instituto Itard
A3: Desenvolvimento Motor
A4: N.º | B4: Verificar se: | C4: Critério | D4: Resultado | E4: Idade
A5: 1 | B5: Alcança um objeto colocado à sua frente (15 a 20 cm.). | C5: Em até 20s após a apresentação do objeto. | D5: S | E5: 0 a 1
A6: 2 | B6: Apanha um objeto colocado à sua frente (8 cm.). | C6: Segurar o objeto com uma ou ambas as mãos, de forma a erguê-lo, mesmo que este caia logo em seguida. | D6: S | E6: 0 a 1
A7: 3 | B7: Estende os braços em direção a um objeto à sua frente e o apanha. | C7: Objeto deve ser colocado cerca de 15 a 20 cm. | D7: S | E7: 0 a 1
A8: 4 | B8: Alcança um objeto preferido. | C8: Objeto deve ser colocado acima de sua cabeça numa distância de 15 a 20 cm. | D8: S | E8: 0 a 1
A9: 5 | B9: Coloca objetos na boca. | D9: S | E9: 0 a 1
A10: 6 | B10: Eleva a cabeça e o tronco apoiando-se nos braços, ao estar deitado de barriga para baixo. | D10: S | E10: 0 a 1
A11: 7 | B11: Levanta a cabeça e o tronco apoiando-se em um só braço. | D11: S | E11: 0 a 1
A12: 8 | B12: Toca e explora objetos com a boca. | D12: S | E12: 0 a 1
A13: 9 | B13: Estando de barriga para baixo, vira de lado e mantém esta posição em 50% das vezes. | C13: Três vezes corretas em 6 tentativas. | D13: S | E13: 0 a 1
A14: 10 | B14: Estando de barriga para baixo, vira de costas. | C14: Colocar um objeto no campo visual da criança e movê-lo para o lado oposto de seu rosto. | D14: S | E14: 0 a 1
A15: 11 | B15: Estando de barriga para baixo, move-se para frente. | D15: S | E15: 0 a 1
A16: 12 | B16: Deitado de costas, rola para o lado. | C16: Rolar para o lado, no máximo um minuto após a apresentação de um brinquedo. | D16: S | E16: 0 a 1
A17: 13 | B17: Deitado de costas, vira de barriga para baixo. | C17: Virar de barriga para baixo, no máximo um minuto após a apresentação de um brinquedo. | D17: S | E17: 0 a 1
A18: 14 | B18: Faz esforço para sentar-se, segurando-se nos dedos se um adulto. | C18: Criança inicialmente deitada. | D18: S | E18: 0 a 1
A19: 15 | B19: Vira a cabeça com facilidade quando o corpo está apoiado. | D19: S | E19: 0 a 1
A20: 16 | B20: Mantém-se sentado por 2 minutos. | D20: S | E20: 0 a 1
A21: 17 | B21: Solta um objeto para apanhar outro. | C21: Colocar no mínimo 2 objetos próximos à criança. | D21: S | E21: 0 a 1
A22: 18 | B22: Apanha e deixa cair um objeto propositalmente. | D22: S | E22: 0 a 1
A23: 19 | B23: Fica em pé com o máximo de apoio. | C23: Criança segurada por um adulto (com ambas as mãos) pela cintura ou sob os ombros. | D23: S | E23: 0 a 1
A24: 20 | B24: Estando em pé com apoio, pula para cima e para baixo. | C24: Criança segurada por um adulto (com ambas as mãos) pela cintura ou sob os ombros. | D24: S | E24: 0 a 1
A25: 21 | B25: Engatinha para apanhar um objeto (distância igual à altura do corpo). | C25: Engatinhar, e não arrastar-se. | D25: S | E25: 0 a 1
A26: 22 | B26: Senta-se, apoiando-se sozinho. | D26: S | E26: 0 a 1
A27: 23 | B27: Estando sentado, vira de gatinhas. | D27: S | E27: 0 a 1
A28: 24 | B28: Estando em barriga para baixo, consegue sentar-se. | D28: S | E28: 0 a 1
A29: 25 | B29: Senta-se sem o apoio das mãos. | C29: Permanecer sentado por 2 min, sem apoiar-se nas mãos. | D29: S | E29: 0 a 1
A30: 26 | B30: Atira objetos ao acaso. | D30: S | E30: 0 a 1
A31: 27 | B31: Balança para frente e para trás quando de gatinhas. | C31: Entrevista com os responsáveis. | D31: S | E31: 0 a 1
A32: 28 | B32: Transfere objetos de uma mão para outra quando sentado. | D32: S | E32: 0 a 1
A33: 29 | B33: Retém em uma das mãos 2 cubos de 2,5 cm. | D33: S | E33: 0 a 1
A34: 30 | B34: Fica de joelhos. | C34: Estando de pé, sentada ou de gatinhas, ajoelha-se. | D34: S | E34: 0 a 1
A35: 31 | B35: Fica em pé, apoiando se em algo. | D35: S | E35: 0 a 1
A36: 32 | B36: Usa preensão de pinça para pegar objetos. | C36: No máximo dentro de 1 min após a apresentação dos objetos. | D36: S | E36: 0 a 1
A37: 33 | B37: Engatinha. | D37: S | E37: 0 a 1
A38: 34 | B38: Estando de gatinhas, estende uma das mãos para o alto ntando alcançar algo. | D38: S | E38: 0 a 1
A39: 35 | B39: Fica em pé com o mínimo de apoio. | C39: Permanece em pé durante 30s. | D39: S | E39: 0 a 1
A40: 36 | B40: Lambe a comida ao redor da boca. | D40: S | E40: 0 a 1
A41: 37 | B41: Mantém se em pé sozinho por um minuto. | D41: S | E41: 0 a 1
...

Sheet Resultados
A1: TABELA SÍNTESE DE RESULTADOS OBTIDOS NO INVENTÁRIO PORTAGE OPERACIONALIZADO (IPO)
A2: =TODAY() -> 46283
A3: INSTIMULAÇÃO INFANTIL 45 ITENS
A4: *Coloque o total da pontuação em cada área avaliada
B5: 12 | C5: 24 | D5: 36 | E5: 48 | F5: 60 | G5: 72
A6: Idade | B6: 0-1 ano | C6: 1-2 anos | D6: 2-3 anos | E6: 3-4 anos | F6: 4-5 anos | G6: 5-6 anos | H6: Global
A7: Áreas | B7: Total | C7: Total | D7: Total | E7: Total | F7: Total | G7: Total
A8: Socialização | B8: =COUNTIF(SOCIALIZAÇÃO!$D$5:$D$32,"S")+(COUNTIF(SOCIALIZAÇÃO!$D$5:$D$32,"AV")/2) -> 28 | C8: =COUNTIF(SOCIALIZAÇÃO!$D$33:$D$47,"S")+(COUNTIF(SOCIALIZAÇÃO!$D$33:$D$47,"AV")/2) -> 15 | D8: =COUNTIF(SOCIALIZAÇÃO!$D$48:$D$55,"S")+(COUNTIF(SOCIALIZAÇÃO!$D$48:$D$55,"AV")/2) -> 8 | E8: =COUNTIF(SOCIALIZAÇÃO!$D$56:$D$67,"S")+(COUNTIF(SOCIALIZAÇÃO!$D$56:$D$67,"AV")/2) -> 12 | F8: =COUNTIF(SOCIALIZAÇÃO!$D$68:$D$76,"S")+(COUNTIF(SOCIALIZAÇÃO!$D$68:$D$76,"AV")/2) -> 9 | G8: =COUNTIF(SOCIALIZAÇÃO!$D$77:$D$87,"S")+(COUNTIF(SOCIALIZAÇÃO!$D$77:$D$87,"AV")/2) -> 11 | H8: =SUM(B8:G8) -> 83
A9: Linguagem | B9: =COUNTIF(LINGUAGEM!$D$5:$D$14,"S")+(COUNTIF(LINGUAGEM!$D$5:$D$14,"AV")/2) -> 10 | C9: =COUNTIF(LINGUAGEM!$D$15:$D$32,"S")+(COUNTIF(LINGUAGEM!$D$15:$D$32,"AV")/2) -> 18 | D9: =COUNTIF(LINGUAGEM!$D$33:$D$62,"S")+(COUNTIF(LINGUAGEM!$D$33:$D$62,"AV")/2) -> 30 | E9: =COUNTIF(LINGUAGEM!$D$63:$D$74,"S")+(COUNTIF(LINGUAGEM!$D$63:$D$74,"AV")/2) -> 12 | F9: =COUNTIF(LINGUAGEM!$D$75:$D$89,"S")+(COUNTIF(LINGUAGEM!$D$75:$D$89,"AV")/2) -> 15 | G9: =COUNTIF(LINGUAGEM!$D$90:$D$104,"S")+(COUNTIF(LINGUAGEM!$D$90:$D$104,"AV")/2) -> 14 | H9: =SUM(B9:G9) -> 99
A10: Autocuidados | B10: =COUNTIF('AUTOS CUIDADOS'!$D$5:$D$17,"S")+(COUNTIF('AUTOS CUIDADOS'!$D$5:$D$17,"AV")/2) -> 13 | C10: =COUNTIF('AUTOS CUIDADOS'!$D$18:$D$29,"S")+(COUNTIF('AUTOS CUIDADOS'!$D$18:$D$29,"AV")/2) -> 12 | D10: =COUNTIF('AUTOS CUIDADOS'!$D$30:$D$56,"S")+(COUNTIF('AUTOS CUIDADOS'!$D$30:$D$56,"AV")/2) -> 27 | E10: =COUNTIF('AUTOS CUIDADOS'!$D$57:$D$71,"S")+(COUNTIF('AUTOS CUIDADOS'!$D$57:$D$71,"AV")/2) -> 15 | F10: =COUNTIF('AUTOS CUIDADOS'!$D$72:$D$94,"S")+(COUNTIF('AUTOS CUIDADOS'!$D$72:$D$94,"AV")/2) -> 23 | G10: =COUNTIF('AUTOS CUIDADOS'!$D$95:$D$109,"S")+(COUNTIF('AUTOS CUIDADOS'!$D$95:$D$109,"AV")/2) -> 15 | H10: =SUM(B10:G10) -> 105
A11: Cognição | B11: =COUNTIF(COGNIÇÃO!$D$5:$D$18,"S")+(COUNTIF(COGNIÇÃO!$D$5:$D$18,"AV")/2) -> 14 | C11: =COUNTIF(COGNIÇÃO!$D$19:$D$28,"S")+(COUNTIF(COGNIÇÃO!$D$19:$D$28,"AV")/2) -> 10 | D11: =COUNTIF(COGNIÇÃO!$D$29:$D$44,"S")+(COUNTIF(COGNIÇÃO!$D$29:$D$44,"AV")/2) -> 16 | E11: =COUNTIF(COGNIÇÃO!$D$45:$D$68,"S")+(COUNTIF(COGNIÇÃO!$D$45:$D$68,"AV")/2) -> 24 | F11: =COUNTIF(COGNIÇÃO!$D$69:$D$90,"S")+(COUNTIF(COGNIÇÃO!$D$69:$D$90,"AV")/2) -> 22 | G11: =COUNTIF(COGNIÇÃO!$D$91:$D$112,"S")+(COUNTIF(COGNIÇÃO!$D$91:$D$112,"AV")/2) -> 22 | H11: =SUM(B11:G11) -> 108
A12: Motora | B12: =COUNTIF(MOTOR!$D$5:$D$49,"S")+(COUNTIF(MOTOR!$D$5:$D$49,"AV")/2) -> 45 | C12: =COUNTIF(MOTOR!$D$50:$D$67,"S")+(COUNTIF(MOTOR!$D$50:$D$67,"AV")/2) -> 18 | D12: =COUNTIF(MOTOR!$D$68:$D$84,"S")+(COUNTIF(MOTOR!$D$68:$D$84,"AV")/2) -> 17 | E12: =COUNTIF(MOTOR!$D$85:$D$99,"S")+(COUNTIF(MOTOR!$D$85:$D$99,"AV")/2) -> 15 | F12: =COUNTIF(MOTOR!$D$100:$D$115,"S")+(COUNTIF(MOTOR!$D$100:$D$115,"AV")/2) -> 16 | G12: =COUNTIF(MOTOR!$D$116:$D$144,"S")+(COUNTIF(MOTOR!$D$116:$D$144,"AV")/2) -> 29 | H12: =SUM(B12:G12) -> 140
A13: Global | B13: =SUM(B8:B12) -> 110 | C13: =SUM(C8:C12) -> 73 | D13: =SUM(D8:D12) -> 98 | E13: =SUM(E8:E12) -> 78 | F13: =SUM(F8:F12) -> 85 | G13: =SUM(G8:G12) -> 91
A15: Tabela para cálculo da idade de desenvolvimento - Guia Portage
A16: Preencha a idade atual e a pontuação do aluno para cada faixa etária | E16: IDADE ATUAL: | F16: 7 | I16: %
A17: Faixa etária | B17: Socialização | C17: Linguagem | D17: Cognição | E17: Auto cuidados | F17: Motor | G17: IDADE MESES | I17: Faixa etária | J17: Socialização | K17: Linguagem | L17: Cognição | M17: Auto cuidados | N17: Motor
A18: 0 a 1 ano | B18: =B8 -> 28 | C18: =B9 -> 10 | D18: =B11 -> 14 | E18: =B10 -> 13 | F18: =B12 -> 45 | G18: =ROUND(((((B18*12)/28)+((C18*12)/10)+((D18*12)/14)+((E18*12)/13)+((F18*12)/45))/60)*12,0)& " Meses" -> 12 Meses | I18: 0 a 1 ano | J18: =B18/28 -> 1 | K18: =C18/10 -> 1 | L18: =D18/14 -> 1 | M18: =E18/13 -> 1 | N18: =F18/45 -> 1
A19: 1 a 2 anos | B19: =C8 -> 15 | C19: =C9 -> 18 | D19: =C11 -> 10 | E19: =C10 -> 12 | F19: =C12 -> 18 | G19: =((((B19*12)/15)+((C19*12)/18)+((D19*12)/10)+((E19*12)/12)+((F19*12)/18))/30)*12 & " meses" -> 24 meses | I19: 1 a 2 anos | J19: =B19/15 -> 1 | K19: =C19/18 -> 1 | L19: =D19/10 -> 1 | M19: =E19/12 -> 1 | N19: =F19/18 -> 1
A20: 2 a 3 anos | B20: =D8 -> 8 | C20: =D9 -> 30 | D20: =D11 -> 16 | E20: =D10 -> 27 | F20: =D12 -> 17 | G20: =((((B20*12)/8)+((C20*12)/30)+((D20*12)/16)+((E20*12)/27)+((F20*12)/17))/20)*12 & " meses" -> 36 meses | I20: 2 a 3 anos | J20: =B20/8 -> 1 | K20: =C20/30 -> 1 | L20: =D20/16 -> 1 | M20: =E20/27 -> 1 | N20: =F20/17 -> 1
A21: 3 a 4 anos | B21: =E8 -> 12 | C21: =E9 -> 12 | D21: =E11 -> 24 | E21: =E10 -> 15 | F21: =E12 -> 15 | G21: =((((B21*12)/12)+((C21*12)/12)+((D21*12)/24)+((E21*12)/15)+((F21*12)/15))/15)*12 & " meses" -> 48 meses | I21: 3 a 4 anos | J21: =B21/12 -> 1 | K21: =C21/12 -> 1 | L21: =D21/24 -> 1 | M21: =E21/15 -> 1 | N21: =F21/15 -> 1
A22: 4 a 5 anos | B22: =F8 -> 9 | C22: =F9 -> 15 | D22: =F11 -> 22 | E22: =F10 -> 23 | F22: =F12 -> 16 | G22: =((((B22*12)/9)+((C22*12)/15)+((D22*12)/22)+((E22*12)/23)+((F22*12)/16))/12)*12 & " meses" -> 60 meses | I22: 4 a 5 anos | J22: =B22/9 -> 1 | K22: =C22/15 -> 1 | L22: =D22/22 -> 1 | M22: =E22/23 -> 1 | N22: =F22/16 -> 1
A23: 5 a 6 anos | B23: =G8 -> 11 | C23: 14 | D23: =G11 -> 22 | E23: =G10 -> 15 | F23: =G12 -> 29 | G23: =((((B23*12)/11)+((C23*12)/14)+((D23*12)/22)+((E23*12)/15)+((F23*12)/29))/10)*12 & " meses" -> 72 meses | I23: 5 a 6 anos | J23: =B23/11 -> 1 | K23: =C23/14 -> 1 | L23: =D23/22 -> 1 | M23: =E23/15 -> 1 | N23: =F23/29 -> 1
A24: RESULTADO da Idade calculada | B24: =ROUND(((((B18*12)/28)+((B19*12)/16)+((B20*12)/8)+((B21*12)/12)+((B22*12)/9)+((B23*12)/11))/12),0) -> 6 | C24: =ROUND(((((C18*12)/10)+((C19*12)/18)+((C20*12)/30)+((C21*12)/24)+((C22*12)/15)+((C23*12)/14))/12),0) -> 6 | D24: =ROUND(((((D18*12)/14)+((D19*12)/10)+((D20*12)/16)+((D21*12)/24)+((D22*12)/22)+((D23*12)/22))/12),0) -> 6 | E24: =ROUND(((((E18*12)/13)+((E19*12)/12)+((E20*12)/27)+((E21*12)/15)+((E22*12)/23)+((E23*12)/15))/12),0) -> 6 | F24: =ROUND(((((F18*12)/45)+((F19*12)/18)+((F20*12)/17)+((F21*12)/15)+((F22*12)/16)+((F23*12)/29))/12),0) -> 6 | G24: =AVERAGE(B24:F24) & " Anos" -> 6 Anos
A25: Obs: O resultado máximo será sempre 6 anos. Esse é apenas um guia para orientar na criação de atividades, não deve ser utilizado para fins de diagnóstico sem um profissional qualificado. Para mais detalhes, baixe o e-book Como Identificar e Adaptar Atividades para Alunos com Deficiência, no site do Instituto Itard. Tabela criada por Leandro Rodrigues. Email: leandro@institutoitard.com.br
A27: % | B27: =F16/F16 -> 1 | C27: 0.86
A28: IDADE COGNITIVA | B28: 7 | C28: =AVERAGE(B24:F24) -> 6

Sheet Calculo da Idade
A1: Tabela para cálculo da idade de desenvolvimento - Guia Portage
A2: Preencha a idade atual e a pontuação do aluno para cada faixa etária | E2: IDADE ATUAL: | F2: 7
A3: Faixa etária | B3: Socialização | C3: Linguagem | D3: Cognição | E3: Auto cuidados | F3: Motor
A4: 0 a 1 ano | B4: 0 | C4: 12 | D4: 13 | E4: 5 | F4: 4
A5: 1 a 2 anos | B5: 0 | C5: 0 | D5: 0 | E5: 0 | F5: 0
A6: 2 a 3 anos | B6: 0 | C6: 0 | D6: 0 | E6: 0 | F6: 0
A7: 3 a 4 anos | B7: 0 | C7: 0 | D7: 0 | E7: 0 | F7: 0
A8: 4 a 5 anos | B8: 0 | C8: 0 | D8: 0 | E8: 0 | F8: 0
A9: 5 a 6 anos | B9: 0 | C9: 0 | D9: 0 | E9: 0 | F9: 0
A10: RESULTADO da Idade calculada | B10: =ROUND(((((B4*12)/28)+((B5*12)/16)+((B6*12)/8)+((B7*12)/12)+((B8*12)/9)+((B9*12)/11))/12),0) & " anos" -> 0 anos | C10: =ROUND(((((C4*12)/10)+((C5*12)/18)+((C6*12)/30)+((C7*12)/24)+((C8*12)/15)+((C9*12)/14))/12),0) & " anos" -> 1 anos | D10: =ROUND(((((D4*12)/14)+((D5*12)/10)+((D6*12)/16)+((D7*12)/24)+((D8*12)/22)+((D9*12)/22))/12),0) & " anos" -> 1 anos | E10: =ROUND(((((E4*12)/13)+((E5*12)/12)+((E6*12)/27)+((E7*12)/15)+((E8*12)/23)+((E9*12)/15))/12),0) & " anos" -> 0 anos | F10: =ROUND(((((F4*12)/45)+((F5*12)/18)+((F6*12)/17)+((F7*12)/15)+((F8*12)/16)+((F9*12)/29))/12),0) & " anos" -> 0 anos
A11: Obs: O resultado máximo será sempre 6 anos. Esse é apenas um guia para orientar na criação de atividades, não deve ser utilizado para fins de diagnóstico sem um profissional qualificado. Para mais detalhes, baixe o e-book Como Identificar e Adaptar Atividades para Alunos com Deficiência, no site do Instituto Itard. Tabela criada por Leandro Rodrigues. Email: leandro@institutoitard.com.br
B12: =((((B4*12)/28)+((B5*12)/16)+((B6*12)/8)+((B7*12)/12)+((B8*12)/9)+((B9*12)/11))/12) -> 0 | C12: =((((C4*12)/10)+((C5*12)/18)+((C6*12)/30)+((C7*12)/24)+((C8*12)/15)+((C9*12)/14))/12) -> 1.2 | D12: =((((D4*12)/14)+((D5*12)/10)+((D6*12)/16)+((D7*12)/24)+((D8*12)/22)+((D9*12)/22))/12) -> 0.92857143 | E12: =((((E4*12)/13)+((E5*12)/12)+((E6*12)/27)+((E7*12)/15)+((E8*12)/23)+((E9*12)/15))/12) -> 0.38461538 | F12: =((((F4*12)/45)+((F5*12)/18)+((F6*12)/17)+((F7*12)/15)+((F8*12)/16)+((F9*12)/29))/12) -> 0.088888889
B13: =IF(F2>6,6,F2) -> 6 | C13: =IF(F2>6,6,F2) -> 6 | D13: =IF(F2>6,6,F2) -> 6 | E13: =IF(F2>6,6,F2) -> 6 | F13: =IF(F2>6,6,F2) -> 6
F14: Importante:
F15: O valor máximo do gráfico é de 6 anos.
F17: Lembrete:
F18: S = 1 ponto, N = 0 pontos e AV = 0,5 ponto.

Sheet Acompanhamento contínuo
A1: TABELA DE ACOMPANHAMENTO CONTÍNUO DOS RESULTADOS OBTIDOS NO INVENTÁRIO PORTAGE OPERACIONALIZADO (IPO)
G3: Avaliador:
G4: Mediador:
G5: Criança:
G6: Data de nascimento:
G7: Data da avaliação:
A10: Socialização
A11: Faixa etária/data | B11: 44317 | C11: 44409 | D11: 44531 | E11: 44593 | F11: 44682 | G11: 44713
A12: 0-1 ano
A13: 1-2 anos
A14: 2-3 anos
A15: 3-4 anos
A16: 4-5 anos
A17: 5-6 anos
A19: Linguagem
A20: Faixa etária/data | B20: 44317 | C20: 44409 | D20: 44531 | E20: 44593 | F20: 44682 | G20: 44713
A21: 0-1 ano
A22: 1-2 anos
A23: 2-3 anos
A24: 3-4 anos
A25: 4-5 anos
A26: 5-6 anos
A28: Cognitiva
A29: Faixa etária/data | B29: 44317 | C29: 44409 | D29: 44531 | E29: 44593 | F29: 44682 | G29: 44713
A30: 0-1 ano
A31: 1-2 anos
A32: 2-3 anos
A33: 3-4 anos
A34: 4-5 anos
A35: 5-6 anos
A37: Autocuidados
A38: Faixa etária/data | B38: 44317 | C38: 44409 | D38: 44531 | E38: 44593 | F38: 44682 | G38: 44713
A39: 0-1 ano
A40: 1-2 anos
A41: 2-3 anos
A42: 3-4 anos
A43: 4-5 anos
A44: 5-6 anos
A46: Motora
A47: Faixa etária/data | B47: 44317 | C47: 44409 | D47: 44531 | E47: 44593 | F47: 44682 | G47: 44713
...

Sheet Plan2
A1: LISTA
A2: S
A3: N
A4: AV
A5: ANULOU
